<?xml version='1.0'?>
<sdf version='1.6'>
  <model name='JetBot'>
    <model name='JetBot'>
      <static>0</static>
      <link name='chassis'>
        <pose frame=''>0 0 0.043 1.5708 -0 1.5708</pose>
        <collision name='collision'>
          <geometry>
            <mesh>
              <scale>0.001 0.001 0.001</scale>
              <uri>model://jetbot/meshes/JetBot-v3-Chassis.dae</uri>
            </mesh>
          </geometry>
          <surface>
            <friction>
              <ode>
                <mu>0</mu>
                <mu2>0</mu2>
                <slip1>1</slip1>
                <slip2>1</slip2>
              </ode>
            </friction>
          </surface>
        </collision>
        <visual name='visual'>
          <geometry>
            <mesh>
              <scale>0.001 0.001 0.001</scale>
              <uri>model://jetbot/meshes/JetBot-v3-Chassis.dae</uri>
            </mesh>
          </geometry>
        </visual>
      </link>
      <link name='left_wheel'>
        <pose frame=''>0.03 0.05125 0.03 0 -0 1.5708</pose>
        <collision name='collision'>
          <geometry>
            <mesh>
              <scale>0.001 0.001 0.001</scale>
              <uri>model://jetbot/meshes/JetBot-v3-Wheel.stl</uri>
            </mesh>
          </geometry>
        </collision>
        <visual name='visual'>
          <geometry>
            <mesh>
              <scale>0.001 0.001 0.001</scale>
              <uri>model://jetbot/meshes/JetBot-v3-Wheel.stl</uri>
            </mesh>
          </geometry>
          <material>
            <ambient>0.1 0.1 0.1 1</ambient>
            <diffuse>0.1 0.1 0.1 1</diffuse>
            <specular>0 0 0 0</specular>
            <emissive>0 0 0 1</emissive>
          </material>
        </visual>
      </link>
      <link name='right_wheel'>
        <pose frame=''>0.03 -0.0595 0.03 0 -0 1.5708</pose>
        <collision name='collision'>
          <geometry>
            <mesh>
              <scale>0.001 0.001 0.001</scale>
              <uri>model://jetbot/meshes/JetBot-v3-Wheel.stl</uri>
            </mesh>
          </geometry>
        </collision>
        <visual name='visual'>
          <geometry>
            <mesh>
              <scale>0.001 0.001 0.001</scale>
              <uri>model://jetbot/meshes/JetBot-v3-Wheel.stl</uri>
            </mesh>
          </geometry>
          <material>
            <ambient>0.1 0.1 0.1 1</ambient>
            <diffuse>0.1 0.1 0.1 1</diffuse>
            <specular>0 0 0 0</specular>
            <emissive>0 0 0 1</emissive>
          </material>
        </visual>
      </link>
      <joint name='left_wheel_hinge' type='revolute'>
        <pose frame=''>0 0 0 0 -0 0</pose>
        <child>left_wheel</child>
        <parent>chassis</parent>
        <axis>
          <xyz>0 1 0</xyz>
          <use_parent_model_frame>1</use_parent_model_frame>
          <limit>
            <lower>-1e+16</lower>
            <upper>1e+16</upper>
          </limit>
        </axis>
      </joint>
      <joint name='right_wheel_hinge' type='revolute'>
        <pose frame=''>0 0 0 0 -0 0</pose>
        <child>right_wheel</child>
        <parent>chassis</parent>
        <axis>
          <xyz>0 1 0</xyz>
          <use_parent_model_frame>1</use_parent_model_frame>
          <limit>
            <lower>-1e+16</lower>
            <upper>1e+16</upper>
          </limit>
        </axis>
      </joint>
      <link name='camera_link'>
        <gravity>0</gravity>
        <pose frame=''>0.055 0 0.0857 0 0.25 0</pose>
        <inertial>
          <mass>0.1</mass>
        </inertial>
        <visual name='visual'>
          <geometry>
            <box>
              <size>0.001 0.001 0.001</size>
            </box>
          </geometry>
        </visual>
        <sensor name='camera' type='camera'>
          <camera name='__default__'>
            <horizontal_fov>2.79253</horizontal_fov>
            <image>
              <width>1280</width>
              <height>720</height>
            </image>
            <clip>
              <near>0.01</near>
              <far>1</far>
            </clip>
          </camera>
          <always_on>1</always_on>
          <update_rate>10</update_rate>
          <visualize>1</visualize>
        </sensor>
      </link>
      <joint name='camera_joint' type='revolute'>
        <parent>chassis</parent>
        <child>camera_link</child>
        <pose frame=''>0 0 0 0 -0 0</pose>
        <axis>
          <xyz>0.1 0 0</xyz>
          <use_parent_model_frame>1</use_parent_model_frame>
          <limit>
            <lower>-1e+16</lower>
            <upper>1e+16</upper>
          </limit>
        </axis>
      </joint>
      <pose frame=''>0 -0 0 0 -0 0</pose>
    </model>
    <static>0</static>
    <allow_auto_disable>1</allow_auto_disable>
  </model>
</sdf>
